Workbook

Sheet Cover
A1: ISLAND DEVELOPMENT CORPORATION (IDC)
A2: Capital Budgeting Analysis — Chiquita Island Quarry Project
A3: Prepared for Maximum Quality Equipment | September 2022
A5: PROJECT OVERVIEW
A6: Proposal: | B6: Maximum to invest 49% equity in IDC, a JV with Caesar Construction, to operate a rock-armour quarry on Chiquita Island.
A7: Total Initial Investment: | B7: ₱ 581.5M | C7: (Equity ₱479M + Debt ₱102.5M)
A8: Production Capacity: | B8: 3.0 million tonnes/year
A9: MPSA Term: | B9: 25 years (reserves ~25 yr)
A10: Contract Horizon: | B10: SMC offers 2-yr; IDC seeks 5-yr; industry norm 10-yr
A12: KEY DECISION METRICS (linked from Scenarios sheet)
B13: 2-Year Case | C13: 5-Year Case | D13: 10-Year Case
A14: NPV (₱ millions) | B14: =Scenarios!B19 -> -59609070 | C14: =Scenarios!C19 -> 1.9784316e+08 | D14: =Scenarios!D19 -> 4.8432895e+08
A15: IRR | B15: =Scenarios!B20 -> 0.051723841 | C15: =Scenarios!C20 -> 0.19867798 | D15: =Scenarios!D20 -> 0.23547073
A16: Payback (years) | B16: =Scenarios!B21 -> 1.9033911 | C16: =Scenarios!C21 -> 4.0233835 | D16: =Scenarios!D21 -> 4.2746716
A17: Decision vs. thresholds | B17: =Scenarios!B22 -> REJECT | C17: =Scenarios!C22 -> MEETS NPV/IRR (payback fails) | D17: =Scenarios!D22 -> MEETS NPV/IRR (payback fails)
A19: WORKBOOK GUIDE
A20: Assumptions | B20: All model inputs: prices, volumes, tax rates, inflation, capex costs, financing terms (BLUE cells editable)
A21: WACC | B21: Comparable-company beta unlever/relever, CAPM cost of equity, WACC calculation
A22: Depreciation | B22: Straight-line schedule for heavy equipment, auxiliary, causeway. Year-5 rehab @ 40% extends heavy equipment life
A23: Loan Schedule | B23: 10-year amortizing loan @ 9.1% on ₱102.5M bank debt
A24: P&L and FCF | B24: 10-year projection: revenue, opex, EBIT, taxes, depreciation add-back, working capital, unlevered FCF
A25: Working Capital | B25: NWC schedule: 60-day A/R, 30-day A/P on variable cost items, ₱100M operating cash, inventory
A26: Scenarios | B26: NPV / IRR / Payback for 2-, 5-, 10-year contract life with terminal values
A28: LEGEND
A29: Blue text | B29: Hardcoded input (user editable)
A30: Black text | B30: Formula / calculation
A31: Green text | B31: Cross-sheet link
A32: Yellow fill | B32: Key assumption worth particular attention

Sheet Recommendation
B1: INVESTMENT RECOMMENDATION MEMO
B2: To: Albert Rodriguez, CEO — Maximum Quality Equipment
B3: From: Maynard Lascano, CFO | Re: Island Development Corporation (IDC) — Capital Budgeting
B5: HEADLINE RECOMMENDATION
B6: Proceed with the IDC investment ONLY if Maximum and CCC can secure a contract of five years or longer from SMC. The 2-year contract SMC currently offers destroys value (NPV –₱60M, IRR 5.2% vs. WACC 11.1%); a 5-year contract creates ₱198M of value (IRR 19.9%); a 10-year horizon creates ₱478M (IRR 23.5%). Rodriguez's "payback under 2 years" threshold is achieved only in the 2-year case — but only because salvaging nearly-new equipment and recovering working capital front-loads cash; this is an artifact of truncating the project, not genuine economic recovery. Standard NPV/IRR rules should dominate.
B10: KEY METRICS (WACC = 11.06%)
B11: Metric | C11: 2-Year | D11: 5-Year | E11: 10-Year | F11: Threshold
B12: NPV (₱M) | C12: =Scenarios!B19/1000000 -> -59.60907 | D12: =Scenarios!C19/1000000 -> 197.84316 | E12: =Scenarios!D19/1000000 -> 484.32895 | F12: > 0
B13: IRR | C13: =Scenarios!B20 -> 0.051723841 | D13: =Scenarios!C20 -> 0.19867798 | E13: =Scenarios!D20 -> 0.23547073 | F13: > 11.06% WACC
B14: Payback (yrs) | C14: =Scenarios!B21 -> 1.9033911 | D14: =Scenarios!C21 -> 4.0233835 | E14: =Scenarios!D21 -> 4.2746716 | F14: < 2.00 (Rodriguez)
B15: Decision | C15: REJECT | D15: ACCEPT | E15: ACCEPT (ideal) | F15: On NPV/IRR basis
B18: INTERPRETATION OF EACH SCENARIO
B19: Why the 2-year case fails economically
B20: The 2-year NPV is negative because heavy-equipment depreciation, the 40% share of revenue going to subcontractors, and the fuel bill (~₱429M/yr) leave only ~₱102M of annual NOPAT. Two years of that — even combined with a ₱473M terminal cash flow from selling nearly-new machines and unwinding working capital — is not enough to recover ₱581.5M of capital at an 11.06% cost. The 1.88-year payback is misleading: it is driven by asset liquidation, not operating generation.
B23: Why the 5-year case works
B24: The reclamation contract generates ~₱102M–₱140M/yr of NOPAT with no year-5 rehab capex needed (the project ends instead of extending), plus a ₱410M terminal cash flow. NPV of ₱198M at WACC and IRR of 19.9% sit comfortably above thresholds. Payback of 4.0 years breaches Rodriguez's personal rule but is normal for capital-intensive quarrying projects.
B27: Why the 10-year case is best
B28: The full industry-norm horizon — consistent with the 25-year MPSA — lets the project absorb the ₱152.4M Year-5 rehab capex and still deliver steady operating FCF plus a ₱398M terminal. NPV ₱478M and IRR 23.5% reflect the value of a long-duration, rights-protected asset.
B32: STRATEGIC CONSIDERATIONS BEYOND NPV
B33: SMC relationship repair
B34: Maximum lost the SMC channel after the 2019 first-generation equipment quality issue. Rodriguez estimates ~₱200M of annual quotations to SMC that are currently failing to convert. The IDC channel — supplying equipment to the JV and building credibility on-site — creates an option to recapture that annualized flow and other SMC infrastructure work. That option value is NOT in the NPV above and should be explicitly credited in Rodriguez's decision.
B37: Environmental & regulatory risk
B38: Reclamation projects face rising pushback (biodiversity loss, flooding in surrounding areas). The Marcos administration's posture on Build Better More is pro-infrastructure but not immune to ESG pressure. A suspension of either the SMC reclamation or IDC's MPSA would materially hit cash flows. The 1% revenue site-rehab allocation is modest; sensitivity testing with a higher environmental compliance cost is advisable.
... B51: 1) Proceed with the 49% equity investment (₱234.7M of Maximum's cash) IF SMC commits to a 5-year minimum. 2) If SMC insists on 2 years, walk away — the math does not support it, even with the equipment-sales option. 3) Negotiate a price-escalation clause tied to inflation (already assumed at 5.4% Y1–5, 3.0% Y6–10) and a take-or-pay volume floor. 4) Plan for the Y5 rehab (₱152.4M) from retained earnings, not new debt — annual FCF comfortably supports it. 5) Commission an independent ESG impact study on Chiquita Island to pre-empt regulatory disruption.

Sheet Assumptions
A1: IDC CAPITAL BUDGETING — KEY ASSUMPTIONS
B2: Value | C2: Unit | D2: Source / Note
A3: MACROECONOMIC
A4: Tax rate (corporate) | B4: 0.25 | C4: % | D4: Philippine CIT; applied to taxable income
A5: Inflation Y1–Y5 (escalation factor) | B5: 0.054 | C5: % | D5: Case p.5: BSP forecast 5.40% for 2022 (text-based; Exh.5 numerically uses 6.3%)
A6: Inflation Y6–Y10 | B6: 0.03 | C6: % | D6: Case page 5; BSP long-run target range
A8: REVENUE & OPERATIONS
A9: Annual production volume | B9: 3000000 | C9: tonnes | D9: Case p.5: "close to 3M tonnes annually"
A10: Selling price Year 1 (2023) | B10: 550 | C10: ₱/tonne | D10: Exh. 5; average of three size grades
A11: Subcontractor hauling cost Y1 | B11: 250 | C11: ₱/tonne | D11: Exh. 4: drill/blast + bulldoze + road + drain + stock + barge
A12: Subcontractor loading cost Y1 | B12: 30 | C12: ₱/tonne | D12: Exh. 4: barge loading
A13: Fuel consumption (monthly) | B13: 641842 | C13: litres | D13: Case p.5
A14: Fuel price Year 1 | B14: 55.7 | C14: ₱/litre | D14: Case p.5 / Exh. 5
A15: Salaries & wages (monthly) | B15: 2500000 | C15: ₱ | D15: 100 people, 2 shifts; inflation-escalated
A16: Non-fuel monthly opex | B16: 1500000 | C16: ₱ | D16: Case p.5; inflation-escalated
A17: National excise tax | B17: 0.04 | C17: % of revenue | D17: MPSA — Mines & Geosciences Bureau
A18: Local government tax | B18: 0.01 | C18: % of revenue | D18: Case p.3
A19: Site rehabilitation | B19: 0.01 | C19: % of revenue | D19: Environmental compliance
A21: CAPITAL EXPENDITURE
A22: Heavy equipment cost | B22: 381000000 | C22: ₱ | D22: Exh. 3 total
A23: Auxiliary equipment & buildings | B23: 48000000 | C23: ₱ | D23: Exh. 3: trucks, gensets, office, mess, accom
A24: of which: mess/office/accom (no maintenance) | B24: 6000000 | C24: ₱ | D24: Office 2M + Mess 1M + Accom 1–3 × 1M
A25: Causeway / site preparation | B25: 50000000 | C25: ₱ | D25: Case p.5
A26: TOTAL INITIAL CAPEX | B26: =B22+B23+B25 -> 479000000 | C26: ₱ | D26: Equity contribution
A27: Heavy equipment salvage (% of acquisition) | B27: 0.12 | C27: % | D27: Case p.5 — scrap/parts value
A28: Heavy equipment useful life | B28: 5 | C28: years | D28: Case p.5
A29: Y5 rehabilitation (% of heavy equip cost) | B29: 0.4 | C29: % | D29: Extends life 5 more years; salvage 12% at Y10
A30: Auxiliary equipment useful life | B30: 10 | C30: years | D30: Case p.5; salvage 0%
A31: Causeway useful life | B31: 10 | C31: years | D31: Case p.5; salvage 12%
A32: Causeway salvage (% of cost) | B32: 0.12 | C32: % | D32: Case p.5
A33: Heavy equipment maintenance | B33: 0.05 | C33: % of cost | D33: Year 1; inflation-escalated thereafter
A34: Auxiliary equipment maintenance | B34: 0.02 | C34: % of cost | D34: Excludes mess/office/accom; inflation-escalated
A36: FINANCING
A37: Total equity contribution | B37: 479000000 | C37: ₱ | D37: Maximum 49% + CCC 51%
A38: Bank loan | B38: 102500000 | C38: ₱ | D38: 10-year amortizing
A39: Cost of debt (interest rate) | B39: 0.091 | C39: % | D39: Case p.5 / endnote 29
A40: Loan term | B40: 10 | C40: years | D40: "approximately 10 years"
A42: WORKING CAPITAL
A43: Operating cash balance | B43: 100000000 | C43: ₱ | D43: Case p.6: fixed level maintained throughout
A44: Spare-parts inventory (Year 0) | B44: 2500000 | C44: ₱ | D44: Grows with inflation
...

Sheet WACC
A1: WEIGHTED AVERAGE COST OF CAPITAL
A3: Step 1 — Unlever comparable betas
A4: Company | B4: Levered β | C4: D/E | D4: Tax rate | E4: Unlevered β | F4: Notes
A5: Semirara Mining and Power | B5: 1.36 | C5: 0.075 | D5: =Assumptions!$B$4 -> 0.25 | E5: =B5/(1+(1-D5)*C5) -> 1.287574 | F5: Exh. 6
A6: Cemex Holdings Philippines | B6: 0.82 | C6: 0.001 | D6: =Assumptions!$B$4 -> 0.25 | E6: =B6/(1+(1-D6)*C6) -> 0.81938546 | F6: Exh. 6
A7: Concrete Aggregates Corp. | B7: 0.37 | C7: 0.019 | D7: =Assumptions!$B$4 -> 0.25 | E7: =B7/(1+(1-D7)*C7) -> 0.36480158 | F7: Exh. 6 (closest pure-play)
A8: Average unlevered β | E8: =AVERAGE(E5:E7) -> 0.82392033
A10: Step 2 — Relever for IDC capital structure
A11: Debt (₱) | B11: =Assumptions!$B$38 -> 102500000
A12: Equity (₱) | B12: =Assumptions!$B$37 -> 479000000
A13: D / E | B13: =B11/B12 -> 0.21398747
A14: D / V | B14: =B11/(B11+B12) -> 0.17626827
A15: E / V | B15: =B12/(B11+B12) -> 0.82373173
A16: Relevered β (Hamada) | B16: =E8*(1+(1-Assumptions!$B$4)*B13) -> 0.95615181
A18: Step 3 — CAPM and WACC
A19: Risk-free rate (10-yr BVAL) | B19: =Assumptions!$B$50 -> 0.061146
A20: Equity risk premium | B20: =Assumptions!$B$51 -> 0.0612
A21: Cost of equity (Re = Rf + β·ERP) | B21: =B19+B16*B20 -> 0.11966249
A22: Cost of debt (pre-tax) | B22: =Assumptions!$B$39 -> 0.091
A23: Tax rate | B23: =Assumptions!$B$4 -> 0.25
A24: After-tax cost of debt | B24: =B22*(1-B23) -> 0.06825
A26: WACC | B26: =B15*B21+B14*B24 -> 0.1106001
A28: NOTES ON METHOD
A29: • Hamada: βU = βL / (1 + (1–T)·D/E); relever: βL* = βU · (1 + (1–T)·D/E*)
A30: • 10-year risk-free selected to match industry-norm project life; WACC is applied to unlevered FCF.
A31: • Comparables: coal miner (Semirara), cement/aggregates (Cemex, CAC) — CAC is the closest pure-play.

Sheet Depreciation
A1: DEPRECIATION SCHEDULE (Straight-line)
B2: Y0 | C2: Y1 | D2: Y2 | E2: Y3 | F2: Y4 | G2: Y5 | H2: Y6 | I2: Y7 | J2: Y8 | K2: Y9 | L2: Y10
B3: 2022 | C3: 2023 | D3: 2024 | E3: 2025 | F3: 2026 | G3: 2027 | H3: 2028 | I3: 2029 | J3: 2030 | K3: 2031 | L3: 2032
A5: HEAVY EQUIPMENT
A6: Initial cost | B6: =Assumptions!$B$22 -> 381000000
A7: Year-5 rehab capex | G7: =Assumptions!$B$22*Assumptions!$B$29 -> 152400000
A8: Salvage value (end of life) | L8: =Assumptions!$B$22*Assumptions!$B$27 -> 45720000
A9: Annual depreciation | C9: =(Assumptions!$B$22-Assumptions!$B$22*Assumptions!$B$27)/Assumptions!$B$28 -> 67056000 | D9: =(Assumptions!$B$22-Assumptions!$B$22*Assumptions!$B$27)/Assumptions!$B$28 -> 67056000 | E9: =(Assumptions!$B$22-Assumptions!$B$22*Assumptions!$B$27)/Assumptions!$B$28 -> 67056000 | F9: =(Assumptions!$B$22-Assumptions!$B$22*Assumptions!$B$27)/Assumptions!$B$28 -> 67056000 | G9: =(Assumptions!$B$22-Assumptions!$B$22*Assumptions!$B$27)/Assumptions!$B$28 -> 67056000 | H9: =Assumptions!$B$22*Assumptions!$B$29/5 -> 30480000 | I9: =Assumptions!$B$22*Assumptions!$B$29/5 -> 30480000 | J9: =Assumptions!$B$22*Assumptions!$B$29/5 -> 30480000 | K9: =Assumptions!$B$22*Assumptions!$B$29/5 -> 30480000 | L9: =Assumptions!$B$22*Assumptions!$B$29/5 -> 30480000
A10: Book value (end of year) | B10: =Assumptions!$B$22 -> 381000000 | C10: =B10-C9 -> 313944000 | D10: =C10-D9 -> 246888000 | E10: =D10-E9 -> 179832000 | F10: =E10-F9 -> 112776000 | G10: =F10+G7-G9 -> 198120000 | H10: =G10-H9 -> 167640000 | I10: =H10-I9 -> 137160000 | J10: =I10-J9 -> 106680000 | K10: =J10-K9 -> 76200000 | L10: =K10-L9+L8 -> 91440000
A12: AUXILIARY EQUIPMENT
A13: Initial cost | B13: =Assumptions!$B$23 -> 48000000
A14: Annual depreciation | C14: =Assumptions!$B$23/Assumptions!$B$30 -> 4800000 | D14: =Assumptions!$B$23/Assumptions!$B$30 -> 4800000 | E14: =Assumptions!$B$23/Assumptions!$B$30 -> 4800000 | F14: =Assumptions!$B$23/Assumptions!$B$30 -> 4800000 | G14: =Assumptions!$B$23/Assumptions!$B$30 -> 4800000 | H14: =Assumptions!$B$23/Assumptions!$B$30 -> 4800000 | I14: =Assumptions!$B$23/Assumptions!$B$30 -> 4800000 | J14: =Assumptions!$B$23/Assumptions!$B$30 -> 4800000 | ... L14: =Assumptions!$B$23/Assumptions!$B$30 -> 4800000
A15: Book value (end of year) | B15: =Assumptions!$B$23 -> 48000000 | C15: =B15-C14 -> 43200000 | D15: =C15-D14 -> 38400000 | E15: =D15-E14 -> 33600000 | F15: =E15-F14 -> 28800000 | G15: =F15-G14 -> 24000000 | H15: =G15-H14 -> 19200000 | I15: =H15-I14 -> 14400000 | J15: =I15-J14 -> 9600000 | ... L15: =K15-L14 -> 0
A17: CAUSEWAY
A18: Initial cost | B18: =Assumptions!$B$25 -> 50000000
A19: Salvage value | L19: =Assumptions!$B$25*Assumptions!$B$32 -> 6000000
A20: Annual depreciation | C20: =(Assumptions!$B$25-Assumptions!$B$25*Assumptions!$B$32)/Assumptions!$B$31 -> 4400000 | D20: =(Assumptions!$B$25-Assumptions!$B$25*Assumptions!$B$32)/Assumptions!$B$31 -> 4400000 | E20: =(Assumptions!$B$25-Assumptions!$B$25*Assumptions!$B$32)/Assumptions!$B$31 -> 4400000 | F20: =(Assumptions!$B$25-Assumptions!$B$25*Assumptions!$B$32)/Assumptions!$B$31 -> 4400000 | G20: =(Assumptions!$B$25-Assumptions!$B$25*Assumptions!$B$32)/Assumptions!$B$31 -> 4400000 | H20: =(Assumptions!$B$25-Assumptions!$B$25*Assumptions!$B$32)/Assumptions!$B$31 -> 4400000 | I20: =(Assumptions!$B$25-Assumptions!$B$25*Assumptions!$B$32)/Assumptions!$B$31 -> 4400000 | J20: =(Assumptions!$B$25-Assumptions!$B$25*Assumptions!$B$32)/Assumptions!$B$31 -> 4400000 | ... L20: =(Assumptions!$B$25-Assumptions!$B$25*Assumptions!$B$32)/Assumptions!$B$31 -> 4400000
A21: Book value (end of year) | B21: =Assumptions!$B$25 -> 50000000 | C21: =B21-C20 -> 45600000 | D21: =C21-D20 -> 41200000 | E21: =D21-E20 -> 36800000 | F21: =E21-F20 -> 32400000 | G21: =F21-G20 -> 28000000 | H21: =G21-H20 -> 23600000 | I21: =H21-I20 -> 19200000 | J21: =I21-J20 -> 14800000 | K21: =J21-K20 -> 10400000 | L21: =K21-L20+L19 -> 12000000
A23: TOTAL DEPRECIATION | C23: =C9+C14+C20 -> 76256000 | D23: =D9+D14+D20 -> 76256000 | E23: =E9+E14+E20 -> 76256000 | F23: =F9+F14+F20 -> 76256000 | G23: =G9+G14+G20 -> 76256000 | H23: =H9+H14+H20 -> 39680000 | I23: =I9+I14+I20 -> 39680000 | J23: =J9+J14+J20 -> 39680000 | ... L23: =L9+L14+L20 -> 39680000
A24: Total NBV (end of year) | B24: =B10+B15+B21 -> 479000000 | C24: =C10+C15+C21 -> 402744000 | D24: =D10+D15+D21 -> 326488000 | E24: =E10+E15+E21 -> 250232000 | F24: =F10+F15+F21 -> 173976000 | G24: =G10+G15+G21 -> 250120000 | H24: =H10+H15+H21 -> 210440000 | I24: =I10+I15+I21 -> 170760000 | ... L24: =L10+L15+L21 -> 103440000
A25: Heavy NBV (end of year) | B25: =B10 -> 381000000 | C25: =C10 -> 313944000 | D25: =D10 -> 246888000 | E25: =E10 -> 179832000 | F25: =F10 -> 112776000 | G25: =G10 -> 198120000 | H25: =H10 -> 167640000 | I25: =I10 -> 137160000 | ... L25: =L10 -> 91440000
A26: Aux NBV (end of year) | B26: =B15 -> 48000000 | C26: =C15 -> 43200000 | D26: =D15 -> 38400000 | E26: =E15 -> 33600000 | F26: =F15 -> 28800000 | G26: =G15 -> 24000000 | H26: =H15 -> 19200000 | I26: =I15 -> 14400000 | ... L26: =L15 -> 0
A27: Causeway NBV (end of year) | B27: =B21 -> 50000000 | C27: =C21 -> 45600000 | D27: =D21 -> 41200000 | E27: =E21 -> 36800000 | F27: =F21 -> 32400000 | G27: =G21 -> 28000000 | H27: =H21 -> 23600000 | I27: =I21 -> 19200000 | ... L27: =L21 -> 12000000

Sheet Loan Schedule
A1: 10-YEAR AMORTIZING LOAN (₱102.5M @ 9.1%)
A3: Principal | B3: =Assumptions!$B$38 -> 102500000
A4: Rate | B4: =Assumptions!$B$39 -> 0.091
A5: Term (yrs) | B5: =Assumptions!$B$40 -> 10
A6: Annual payment (PMT) | B6: =PMT(B4,B5,-B3) -> 16041929
A8: Year | B8: Beg Balance | C8: Interest | D8: Principal | E8: Payment | F8: End Balance
A9: 1 | B9: =B3 -> 102500000 | C9: =B9*$B$4 -> 9327500 | D9: =E9-C9 -> 6714429 | E9: =$B$6 -> 16041929 | F9: =B9-D9 -> 95785571
A10: 2 | B10: =F9 -> 95785571 | C10: =B10*$B$4 -> 8716487 | D10: =E10-C10 -> 7325442 | E10: =$B$6 -> 16041929 | F10: =B10-D10 -> 88460129
A11: 3 | B11: =F10 -> 88460129 | C11: =B11*$B$4 -> 8049871.7 | D11: =E11-C11 -> 7992057.2 | E11: =$B$6 -> 16041929 | F11: =B11-D11 -> 80468072
A12: 4 | B12: =F11 -> 80468072 | C12: =B12*$B$4 -> 7322594.5 | D12: =E12-C12 -> 8719334.4 | E12: =$B$6 -> 16041929 | F12: =B12-D12 -> 71748737
A13: 5 | B13: =F12 -> 71748737 | C13: =B13*$B$4 -> 6529135.1 | D13: =E13-C13 -> 9512793.8 | E13: =$B$6 -> 16041929 | F13: =B13-D13 -> 62235944
A14: 6 | B14: =F13 -> 62235944 | C14: =B14*$B$4 -> 5663470.9 | D14: =E14-C14 -> 10378458 | E14: =$B$6 -> 16041929 | F14: =B14-D14 -> 51857486
A15: 7 | B15: =F14 -> 51857486 | C15: =B15*$B$4 -> 4719031.2 | D15: =E15-C15 -> 11322898 | E15: =$B$6 -> 16041929 | F15: =B15-D15 -> 40534588
A16: 8 | B16: =F15 -> 40534588 | C16: =B16*$B$4 -> 3688647.5 | D16: =E16-C16 -> 12353281 | E16: =$B$6 -> 16041929 | F16: =B16-D16 -> 28181306
A17: 9 | B17: =F16 -> 28181306 | C17: =B17*$B$4 -> 2564498.9 | D17: =E17-C17 -> 13477430 | E17: =$B$6 -> 16041929 | F17: =B17-D17 -> 14703876
A18: 10 | B18: =F17 -> 14703876 | C18: =B18*$B$4 -> 1338052.7 | D18: =E18-C18 -> 14703876 | E18: =$B$6 -> 16041929 | F18: =B18-D18 -> -8.0093741e-08
A19: Total | C19: =SUM(C9:C18) -> 57919290 | D19: =SUM(D9:D18) -> 1.025e+08 | E19: =SUM(E9:E18) -> 1.6041929e+08

Sheet Working Capital
A1: WORKING CAPITAL SCHEDULE (₱)
B2: Year 0 | C2: Year 1 | D2: Year 2 | E2: Year 3 | F2: Year 4 | G2: Year 5 | H2: Year 6 | I2: Year 7 | J2: Year 8 | K2: Year 9 | L2: Year 10
B3: 2022 | C3: 2023 | D3: 2024 | E3: 2025 | F3: 2026 | G3: 2027 | H3: 2028 | I3: 2029 | J3: 2030 | K3: 2031 | L3: 2032
A5: Operating cash | B5: =Assumptions!$B$43 -> 100000000 | C5: =Assumptions!$B$43 -> 100000000 | D5: =Assumptions!$B$43 -> 100000000 | E5: =Assumptions!$B$43 -> 100000000 | F5: =Assumptions!$B$43 -> 100000000 | G5: =Assumptions!$B$43 -> 100000000 | H5: =Assumptions!$B$43 -> 100000000 | I5: =Assumptions!$B$43 -> 100000000 | ... L5: =Assumptions!$B$43 -> 100000000
A6: Spare-parts inventory | B6: =Assumptions!$B$44 -> 2500000 | C6: =B6*(1+Assumptions!$B$5) -> 2635000 | D6: =C6*(1+Assumptions!$B$5) -> 2777290 | E6: =D6*(1+Assumptions!$B$5) -> 2927263.7 | F6: =E6*(1+Assumptions!$B$5) -> 3085335.9 | G6: =F6*(1+Assumptions!$B$5) -> 3251944 | H6: =G6*(1+Assumptions!$B$6) -> 3349502.4 | I6: =H6*(1+Assumptions!$B$6) -> 3449987.4 | J6: =I6*(1+Assumptions!$B$6) -> 3553487.1 | K6: =J6*(1+Assumptions!$B$6) -> 3660091.7 | L6: =K6*(1+Assumptions!$B$6) -> 3769894.4
A7: Accounts receivable (60 days) | B7: 0 | C7: ='P&L and FCF'!C9*Assumptions!$B$45/Assumptions!$B$47 -> 275000000 | D7: ='P&L and FCF'!D9*Assumptions!$B$45/Assumptions!$B$47 -> 2.8985e+08 | E7: ='P&L and FCF'!E9*Assumptions!$B$45/Assumptions!$B$47 -> 3.055019e+08 | F7: ='P&L and FCF'!F9*Assumptions!$B$45/Assumptions!$B$47 -> 3.21999e+08 | G7: ='P&L and FCF'!G9*Assumptions!$B$45/Assumptions!$B$47 -> 3.3938695e+08 | H7: ='P&L and FCF'!H9*Assumptions!$B$45/Assumptions!$B$47 -> 3.4956856e+08 | I7: ='P&L and FCF'!I9*Assumptions!$B$45/Assumptions!$B$47 -> 3.6005561e+08 | J7: ='P&L and FCF'!J9*Assumptions!$B$45/Assumptions!$B$47 -> 3.7085728e+08 | ... L7: ='P&L and FCF'!L9*Assumptions!$B$45/Assumptions!$B$47 -> 3.9344249e+08
A8: Accounts payable (30 days) | B8: 0 | C8: =('P&L and FCF'!C13+'P&L and FCF'!C15+'P&L and FCF'!C17)*Assumptions!$B$46/Assumptions!$B$47 -> 1.057506e+08 | D8: =('P&L and FCF'!D13+'P&L and FCF'!D15+'P&L and FCF'!D17)*Assumptions!$B$46/Assumptions!$B$47 -> 1.1146113e+08 | E8: =('P&L and FCF'!E13+'P&L and FCF'!E15+'P&L and FCF'!E17)*Assumptions!$B$46/Assumptions!$B$47 -> 1.1748003e+08 | F8: =('P&L and FCF'!F13+'P&L and FCF'!F15+'P&L and FCF'!F17)*Assumptions!$B$46/Assumptions!$B$47 -> 1.2382395e+08 | G8: =('P&L and FCF'!G13+'P&L and FCF'!G15+'P&L and FCF'!G17)*Assumptions!$B$46/Assumptions!$B$47 -> 1.3051045e+08 | H8: =('P&L and FCF'!H13+'P&L and FCF'!H15+'P&L and FCF'!H17)*Assumptions!$B$46/Assumptions!$B$47 -> 1.3442576e+08 | I8: =('P&L and FCF'!I13+'P&L and FCF'!I15+'P&L and FCF'!I17)*Assumptions!$B$46/Assumptions!$B$47 -> 1.3845853e+08 | J8: =('P&L and FCF'!J13+'P&L and FCF'!J15+'P&L and FCF'!J17)*Assumptions!$B$46/Assumptions!$B$47 -> 1.4261229e+08 | ... L8: =('P&L and FCF'!L13+'P&L and FCF'!L15+'P&L and FCF'!L17)*Assumptions!$B$46/Assumptions!$B$47 -> 1.5129738e+08
A9: Net Working Capital | B9: =B5+B6+B7-B8 -> 102500000 | C9: =C5+C6+C7-C8 -> 2.718844e+08 | D9: =D5+D6+D7-D8 -> 2.8116616e+08 | E9: =E5+E6+E7-E8 -> 2.9094913e+08 | F9: =F5+F6+F7-F8 -> 3.0126038e+08 | G9: =G5+G6+G7-G8 -> 3.1212844e+08 | H9: =H5+H6+H7-H8 -> 3.184923e+08 | I9: =I5+I6+I7-I8 -> 3.2504707e+08 | ... L9: =L5+L6+L7-L8 -> 3.4591501e+08
A11: Δ NWC (investment) | B11: =B9 -> 102500000 | C11: =C9-B9 -> 1.693844e+08 | D11: =D9-C9 -> 9281757.6 | E11: =E9-D9 -> 9782972.5 | F11: =F9-E9 -> 10311253 | G11: =G9-F9 -> 10868061 | H11: =H9-G9 -> 6363853.3 | I11: =I9-H9 -> 6554768.9 | J11: =J9-I9 -> 6751412 | ... L11: =L9-K9 -> 7162573

Sheet P&L and FCF
A1: P&L AND UNLEVERED FREE CASH FLOW (₱)
B2: Year 0 | C2: Year 1 | D2: Year 2 | E2: Year 3 | F2: Year 4 | G2: Year 5 | H2: Year 6 | I2: Year 7 | J2: Year 8 | K2: Year 9 | L2: Year 10
B3: 2022 | C3: 2023 | D3: 2024 | E3: 2025 | F3: 2026 | G3: 2027 | H3: 2028 | I3: 2029 | J3: 2030 | K3: 2031 | L3: 2032
A4: Inflation factor (cumulative, Y1=1) | B4: 1 | C4: 1 | D4: =C4*(1+Assumptions!$B$5) -> 1.054 | E4: =D4*(1+Assumptions!$B$5) -> 1.110916 | F4: =E4*(1+Assumptions!$B$5) -> 1.1709055 | G4: =F4*(1+Assumptions!$B$5) -> 1.2341344 | H4: =G4*(1+Assumptions!$B$6) -> 1.2711584 | I4: =H4*(1+Assumptions!$B$6) -> 1.3092931 | J4: =I4*(1+Assumptions!$B$6) -> 1.3485719 | K4: =J4*(1+Assumptions!$B$6) -> 1.3890291 | L4: =K4*(1+Assumptions!$B$6) -> 1.4307
A6: REVENUE
A7: Volume (tonnes) | C7: =Assumptions!$B$9 -> 3000000 | D7: =Assumptions!$B$9 -> 3000000 | E7: =Assumptions!$B$9 -> 3000000 | F7: =Assumptions!$B$9 -> 3000000 | G7: =Assumptions!$B$9 -> 3000000 | H7: =Assumptions!$B$9 -> 3000000 | I7: =Assumptions!$B$9 -> 3000000 | J7: =Assumptions!$B$9 -> 3000000 | ... L7: =Assumptions!$B$9 -> 3000000
A8: Price (₱/tonne) | C8: =Assumptions!$B$10 -> 550 | D8: =C8*(1+Assumptions!$B$5) -> 579.7 | E8: =D8*(1+Assumptions!$B$5) -> 611.0038 | F8: =E8*(1+Assumptions!$B$5) -> 643.99801 | G8: =F8*(1+Assumptions!$B$5) -> 678.7739 | H8: =G8*(1+Assumptions!$B$6) -> 699.13711 | I8: =H8*(1+Assumptions!$B$6) -> 720.11123 | J8: =I8*(1+Assumptions!$B$6) -> 741.71456 | K8: =J8*(1+Assumptions!$B$6) -> 763.966 | L8: =K8*(1+Assumptions!$B$6) -> 786.88498
A9: Revenue | C9: =C7*C8 -> 1650000000 | D9: =D7*D8 -> 1.7391e+09 | E9: =E7*E8 -> 1.8330114e+09 | F9: =F7*F8 -> 1.931994e+09 | G9: =G7*G8 -> 2.0363217e+09 | H9: =H7*H8 -> 2.0974113e+09 | I9: =I7*I8 -> 2.1603337e+09 | J9: =J7*J8 -> 2.2251437e+09 | ... L9: =L7*L8 -> 2.3606549e+09
A11: OPERATING COSTS
A12: Subcontractor hauling rate (₱/t) | C12: =Assumptions!$B$11 -> 250 | D12: =C12*(1+Assumptions!$B$5) -> 263.5 | E12: =D12*(1+Assumptions!$B$5) -> 277.729 | F12: =E12*(1+Assumptions!$B$5) -> 292.72637 | G12: =F12*(1+Assumptions!$B$5) -> 308.53359 | H12: =G12*(1+Assumptions!$B$6) -> 317.7896 | I12: =H12*(1+Assumptions!$B$6) -> 327.32329 | J12: =I12*(1+Assumptions!$B$6) -> 337.14298 | K12: =J12*(1+Assumptions!$B$6) -> 347.25727 | L12: =K12*(1+Assumptions!$B$6) -> 357.67499
A13: Subcontractor hauling | C13: =C7*C12 -> 750000000 | D13: =D7*D12 -> 790500000 | E13: =E7*E12 -> 833187000 | F13: =F7*F12 -> 878179098 | G13: =G7*G12 -> 9.2560077e+08 | H13: =H7*H12 -> 9.5336879e+08 | I13: =I7*I12 -> 9.8196986e+08 | J13: =J7*J12 -> 1.011429e+09 | ... L13: =L7*L12 -> 1.073025e+09
A14: Subcontractor loading rate (₱/t) | C14: =Assumptions!$B$12 -> 30 | D14: =C14*(1+Assumptions!$B$5) -> 31.62 | E14: =D14*(1+Assumptions!$B$5) -> 33.32748 | F14: =E14*(1+Assumptions!$B$5) -> 35.127164 | G14: =F14*(1+Assumptions!$B$5) -> 37.024031 | H14: =G14*(1+Assumptions!$B$6) -> 38.134752 | I14: =H14*(1+Assumptions!$B$6) -> 39.278794 | J14: =I14*(1+Assumptions!$B$6) -> 40.457158 | K14: =J14*(1+Assumptions!$B$6) -> 41.670873 | L14: =K14*(1+Assumptions!$B$6) -> 42.920999
A15: Subcontractor loading | C15: =C7*C14 -> 90000000 | D15: =D7*D14 -> 94860000 | E15: =E7*E14 -> 99982440 | F15: =F7*F14 -> 1.0538149e+08 | G15: =G7*G14 -> 1.1107209e+08 | H15: =H7*H14 -> 1.1440426e+08 | I15: =I7*I14 -> 1.1783638e+08 | J15: =J7*J14 -> 1.2137147e+08 | ... L15: =L7*L14 -> 1.28763e+08
A16: Fuel price (₱/litre) | C16: =Assumptions!$B$14 -> 55.7 | D16: =C16*(1+Assumptions!$B$5) -> 58.7078 | E16: =D16*(1+Assumptions!$B$5) -> 61.878021 | F16: =E16*(1+Assumptions!$B$5) -> 65.219434 | G16: =F16*(1+Assumptions!$B$5) -> 68.741284 | H16: =G16*(1+Assumptions!$B$6) -> 70.803522 | I16: =H16*(1+Assumptions!$B$6) -> 72.927628 | J16: =I16*(1+Assumptions!$B$6) -> 75.115457 | K16: =J16*(1+Assumptions!$B$6) -> 77.368921 | L16: =K16*(1+Assumptions!$B$6) -> 79.689988
A17: Fuel expense | C17: =Assumptions!$B$13*12*C16 -> 4.2900719e+08 | D17: =Assumptions!$B$13*12*D16 -> 4.5217358e+08 | E17: =Assumptions!$B$13*12*E16 -> 4.7659095e+08 | F17: =Assumptions!$B$13*12*F16 -> 5.0232687e+08 | G17: =Assumptions!$B$13*12*G16 -> 5.2945252e+08 | H17: =Assumptions!$B$13*12*H16 -> 5.4533609e+08 | I17: =Assumptions!$B$13*12*I16 -> 5.6169618e+08 | J17: =Assumptions!$B$13*12*J16 -> 5.7854706e+08 | ... L17: =Assumptions!$B$13*12*L16 -> 6.1378058e+08
A18: Salaries & wages | C18: =Assumptions!$B$15*12 -> 30000000 | D18: =C18*(1+Assumptions!$B$5) -> 31620000 | E18: =D18*(1+Assumptions!$B$5) -> 33327480 | F18: =E18*(1+Assumptions!$B$5) -> 35127164 | G18: =F18*(1+Assumptions!$B$5) -> 37024031 | H18: =G18*(1+Assumptions!$B$6) -> 38134752 | I18: =H18*(1+Assumptions!$B$6) -> 39278794 | J18: =I18*(1+Assumptions!$B$6) -> 40457158 | K18: =J18*(1+Assumptions!$B$6) -> 41670873 | L18: =K18*(1+Assumptions!$B$6) -> 42920999
A19: Other non-fuel expenses | C19: =Assumptions!$B$16*12 -> 18000000 | D19: =C19*(1+Assumptions!$B$5) -> 18972000 | E19: =D19*(1+Assumptions!$B$5) -> 19996488 | F19: =E19*(1+Assumptions!$B$5) -> 21076298 | G19: =F19*(1+Assumptions!$B$5) -> 22214418 | H19: =G19*(1+Assumptions!$B$6) -> 22880851 | I19: =H19*(1+Assumptions!$B$6) -> 23567277 | J19: =I19*(1+Assumptions!$B$6) -> 24274295 | K19: =J19*(1+Assumptions!$B$6) -> 25002524 | L19: =K19*(1+Assumptions!$B$6) -> 25752599
A20: Heavy equipment maintenance | C20: =Assumptions!$B$22*Assumptions!$B$33 -> 19050000 | D20: =C20*(1+Assumptions!$B$5) -> 20078700 | E20: =D20*(1+Assumptions!$B$5) -> 21162950 | F20: =E20*(1+Assumptions!$B$5) -> 22305749 | G20: =F20*(1+Assumptions!$B$5) -> 23510260 | H20: =G20*(1+Assumptions!$B$6) -> 24215567 | I20: =H20*(1+Assumptions!$B$6) -> 24942034 | J20: =I20*(1+Assumptions!$B$6) -> 25690295 | K20: =J20*(1+Assumptions!$B$6) -> 26461004 | L20: =K20*(1+Assumptions!$B$6) -> 27254834
A21: Auxiliary equipment maintenance | C21: =(Assumptions!$B$23-Assumptions!$B$24)*Assumptions!$B$34 -> 840000 | D21: =C21*(1+Assumptions!$B$5) -> 885360 | E21: =D21*(1+Assumptions!$B$5) -> 933169.44 | F21: =E21*(1+Assumptions!$B$5) -> 983560.59 | G21: =F21*(1+Assumptions!$B$5) -> 1036672.9 | H21: =G21*(1+Assumptions!$B$6) -> 1067773 | I21: =H21*(1+Assumptions!$B$6) -> 1099806.2 | J21: =I21*(1+Assumptions!$B$6) -> 1132800.4 | K21: =J21*(1+Assumptions!$B$6) -> 1166784.4 | L21: =K21*(1+Assumptions!$B$6) -> 1201788
A22: Causeway maintenance | C22: =Depreciation!C20*0.5 -> 2200000 | D22: =Depreciation!D20*0.5 -> 2200000 | E22: =Depreciation!E20*0.5 -> 2200000 | F22: =Depreciation!F20*0.5 -> 2200000 | G22: =Depreciation!G20*0.5 -> 2200000 | H22: =Depreciation!H20*0.5 -> 2200000 | I22: =Depreciation!I20*0.5 -> 2200000 | J22: =Depreciation!J20*0.5 -> 2200000 | ... L22: =Depreciation!L20*0.5 -> 2200000
A23: Site rehabilitation (1% of revenue) | C23: =C9*Assumptions!$B$19 -> 16500000 | D23: =D9*Assumptions!$B$19 -> 17391000 | E23: =E9*Assumptions!$B$19 -> 18330114 | F23: =F9*Assumptions!$B$19 -> 19319940 | G23: =G9*Assumptions!$B$19 -> 20363217 | H23: =H9*Assumptions!$B$19 -> 20974113 | I23: =I9*Assumptions!$B$19 -> 21603337 | J23: =J9*Assumptions!$B$19 -> 22251437 | ... L23: =L9*Assumptions!$B$19 -> 23606549
A24: National excise tax (4% of revenue) | C24: =C9*Assumptions!$B$17 -> 66000000 | D24: =D9*Assumptions!$B$17 -> 69564000 | E24: =E9*Assumptions!$B$17 -> 73320456 | F24: =F9*Assumptions!$B$17 -> 77279761 | G24: =G9*Assumptions!$B$17 -> 81452868 | H24: =H9*Assumptions!$B$17 -> 83896454 | I24: =I9*Assumptions!$B$17 -> 86413347 | J24: =J9*Assumptions!$B$17 -> 89005748 | ... L24: =L9*Assumptions!$B$17 -> 94426198
A25: Local government tax (1% of revenue) | C25: =C9*Assumptions!$B$18 -> 16500000 | D25: =D9*Assumptions!$B$18 -> 17391000 | E25: =E9*Assumptions!$B$18 -> 18330114 | F25: =F9*Assumptions!$B$18 -> 19319940 | G25: =G9*Assumptions!$B$18 -> 20363217 | H25: =H9*Assumptions!$B$18 -> 20974113 | I25: =I9*Assumptions!$B$18 -> 21603337 | J25: =J9*Assumptions!$B$18 -> 22251437 | ... L25: =L9*Assumptions!$B$18 -> 23606549
A26: Total operating costs | C26: =SUM(C13,C15,C17,C18,C19,C20,C21,C22,C23,C24,C25) -> 1.4380972e+09 | D26: =SUM(D13,D15,D17,D18,D19,D20,D21,D22,D23,D24,D25) -> 1.5156356e+09 | E26: =SUM(E13,E15,E17,E18,E19,E20,E21,E22,E23,E24,E25) -> 1.5973612e+09 | F26: =SUM(F13,F15,F17,F18,F19,F20,F21,F22,F23,F24,F25) -> 1.6834999e+09 | G26: =SUM(G13,G15,G17,G18,G19,G20,G21,G22,G23,G24,G25) -> 1.7742901e+09 | H26: =SUM(H13,H15,H17,H18,H19,H20,H21,H22,H23,H24,H25) -> 1.8274528e+09 | I26: =SUM(I13,I15,I17,I18,I19,I20,I21,I22,I23,I24,I25) -> 1.8822103e+09 | J26: =SUM(J13,J15,J17,J18,J19,J20,J21,J22,J23,J24,J25) -> 1.9386107e+09 | ... L26: =SUM(L13,L15,L17,L18,L19,L20,L21,L22,L23,L24,L25) -> 2.0565381e+09
A28: EBITDA | C28: =C9-C26 -> 2.1190281e+08 | D28: =D9-D26 -> 2.2346436e+08 | E28: =E9-E26 -> 2.3565023e+08 | F28: =F9-F26 -> 2.4849415e+08 | G28: =G9-G26 -> 2.6203163e+08 | H28: =H9-H26 -> 2.6995858e+08 | I28: =I9-I26 -> 2.7812334e+08 | J28: =J9-J26 -> 2.8653304e+08 | ... L28: =L9-L26 -> 3.0411688e+08
A29: Depreciation | C29: =Depreciation!C23 -> 76256000 | D29: =Depreciation!D23 -> 76256000 | E29: =Depreciation!E23 -> 76256000 | F29: =Depreciation!F23 -> 76256000 | G29: =Depreciation!G23 -> 76256000 | H29: =Depreciation!H23 -> 39680000 | I29: =Depreciation!I23 -> 39680000 | J29: =Depreciation!J23 -> 39680000 | ... L29: =Depreciation!L23 -> 39680000
A30: EBIT | C30: =C28-C29 -> 1.3564681e+08 | D30: =D28-D29 -> 1.4720836e+08 | E30: =E28-E29 -> 1.5939423e+08 | F30: =F28-F29 -> 1.7223815e+08 | G30: =G28-G29 -> 1.8577563e+08 | H30: =H28-H29 -> 2.3027858e+08 | I30: =I28-I29 -> 2.3844334e+08 | J30: =J28-J29 -> 2.4685304e+08 | ... L30: =L28-L29 -> 2.6443688e+08
A31: Tax on EBIT (25%) | C31: =MAX(0,C30)*Assumptions!$B$4 -> 33911702 | D31: =MAX(0,D30)*Assumptions!$B$4 -> 36802090 | E31: =MAX(0,E30)*Assumptions!$B$4 -> 39848559 | F31: =MAX(0,F30)*Assumptions!$B$4 -> 43059537 | G31: =MAX(0,G30)*Assumptions!$B$4 -> 46443908 | H31: =MAX(0,H30)*Assumptions!$B$4 -> 57569645 | I31: =MAX(0,I30)*Assumptions!$B$4 -> 59610834 | J31: =MAX(0,J30)*Assumptions!$B$4 -> 61713259 | ... L31: =MAX(0,L30)*Assumptions!$B$4 -> 66109220
A32: NOPAT = EBIT × (1–T) | C32: =C30-C31 -> 1.0173511e+08 | D32: =D30-D31 -> 1.1040627e+08 | E32: =E30-E31 -> 1.1954568e+08 | F32: =F30-F31 -> 1.2917861e+08 | G32: =G30-G31 -> 1.3933172e+08 | H32: =H30-H31 -> 1.7270893e+08 | I32: =I30-I31 -> 1.788325e+08 | J32: =J30-J31 -> 1.8513978e+08 | ... L32: =L30-L31 -> 1.9832766e+08
A34: UNLEVERED FREE CASH FLOW BUILD
A35: NOPAT | C35: =C32 -> 1.0173511e+08 | D35: =D32 -> 1.1040627e+08 | E35: =E32 -> 1.1954568e+08 | F35: =F32 -> 1.2917861e+08 | G35: =G32 -> 1.3933172e+08 | H35: =H32 -> 1.7270893e+08 | I35: =I32 -> 1.788325e+08 | J35: =J32 -> 1.8513978e+08 | ... L35: =L32 -> 1.9832766e+08
A36: (+) Depreciation | C36: =C29 -> 76256000 | D36: =D29 -> 76256000 | E36: =E29 -> 76256000 | F36: =F29 -> 76256000 | G36: =G29 -> 76256000 | H36: =H29 -> 39680000 | I36: =I29 -> 39680000 | J36: =J29 -> 39680000 | ... L36: =L29 -> 39680000
A37: (–) Capex | B37: =-Assumptions!$B$26 -> -479000000 | C37: 0 | D37: 0 | E37: 0 | F37: 0 | G37: =-Depreciation!G7 -> -152400000 | H37: 0 | I37: 0 | J37: 0 | K37: 0 | L37: 0
A38: (–) Change in NWC | B38: =-'Working Capital'!B11 -> -102500000 | C38: =-'Working Capital'!C11 -> -1.693844e+08 | D38: =-'Working Capital'!D11 -> -9281757.6 | E38: =-'Working Capital'!E11 -> -9782972.5 | F38: =-'Working Capital'!F11 -> -10311253 | G38: =-'Working Capital'!G11 -> -10868061 | H38: =-'Working Capital'!H11 -> -6363853.3 | I38: =-'Working Capital'!I11 -> -6554768.9 | ... L38: =-'Working Capital'!L11 -> -7162573
A39: (+) Terminal proceeds (Y10 base case) | L39: =Assumptions!$B$22*Assumptions!$B$27+Assumptions!$B$25*Assumptions!$B$32 -> 51720000
A40: (+) Recovery of NWC (Y10) | L40: ='Working Capital'!L8 -> 1.5129738e+08
A42: UNLEVERED FCF | B42: =B37+B38 -> -581500000 | C42: =C35+C36+C37+C38 -> 8606704.8 | D42: =D35+D36+D37+D38+D39 -> 1.7738051e+08 | E42: =E35+E36+E37+E38 -> 1.860187e+08 | F42: =F35+F36+F37+F38 -> 1.9512336e+08 | G42: =G35+G36+G37+G38 -> 52319662 | H42: =H35+H36+H37+H38 -> 2.0602508e+08 | I42: =I35+I36+I37+I38 -> 2.1195773e+08 | J42: =J35+J36+J37+J38 -> 2.1806837e+08 | K42: =K35+K36+K37+K38 -> 2.2436232e+08 | L42: =L35+L36+L37+L38+L39+L40 -> 4.3386247e+08
A43: Cumulative FCF | B43: =B42 -> -581500000 | C43: =B43+C42 -> -5.728933e+08 | D43: =C43+D42 -> -3.9551278e+08 | E43: =D43+E42 -> -2.0949408e+08 | F43: =E43+F42 -> -14370724 | G43: =F43+G42 -> 37948939 | H43: =G43+H42 -> 2.4397402e+08 | I43: =H43+I42 -> 4.5593175e+08 | J43: =I43+J42 -> 6.7400012e+08 | ... L43: =K43+L42 -> 1.3322249e+09
A44: Discount factor @ WACC | B44: =1/(1+WACC!$B$26)^0 -> 1 | C44: =1/(1+WACC!$B$26)^1 -> 0.90041411 | D44: =1/(1+WACC!$B$26)^2 -> 0.81074557 | E44: =1/(1+WACC!$B$26)^3 -> 0.73000675 | F44: =1/(1+WACC!$B$26)^4 -> 0.65730838 | G44: =1/(1+WACC!$B$26)^5 -> 0.59184974 | H44: =1/(1+WACC!$B$26)^6 -> 0.53290985 | I44: =1/(1+WACC!$B$26)^7 -> 0.47983955 | J44: =1/(1+WACC!$B$26)^8 -> 0.4320543 | K44: =1/(1+WACC!$B$26)^9 -> 0.38902779 | L44: =1/(1+WACC!$B$26)^10 -> 0.35028611
A45: PV of FCF | B45: =B42*B44 -> -581500000 | C45: =C42*C44 -> 7749598.4 | D45: =D42*D44 -> 1.4381046e+08 | E45: =E42*E44 -> 1.3579491e+08 | F45: =F42*F44 -> 1.2825622e+08 | G45: =G42*G44 -> 30965378 | H45: =H42*H44 -> 1.097928e+08 | I45: =I42*I44 -> 1.017057e+08 | ... L45: =L42*L44 -> 1.51976e+08

Sheet Scenarios
A1: SCENARIO ANALYSIS — NPV, IRR & PAYBACK
A3: Project life | B3: 2-Year Contract | C3: 5-Year Contract | D3: 10-Year Contract
A4: Years | B4: 2 | C4: 5 | D4: 10
A6: TERMINAL VALUE CALCULATIONS
A7: Salvage value — Heavy (12% of cost) | B7: =Assumptions!$B$22*Assumptions!$B$27 -> 45720000 | C7: =Assumptions!$B$22*Assumptions!$B$27 -> 45720000 | D7: =Assumptions!$B$22*Assumptions!$B$27 -> 45720000
A8: Book value — Heavy (from Dep sheet) | B8: =Depreciation!D25 -> 246888000 | C8: =Assumptions!$B$22*Assumptions!$B$27 -> 45720000 | D8: =Depreciation!L25 -> 91440000
A9: Gain (loss) on Heavy sale | B9: =B7-B8 -> -201168000 | C9: =C7-C8 -> 0 | D9: =D7-D8 -> -45720000
A10: Tax on gain (shield on loss) | B10: =B9*Assumptions!$B$4 -> -50292000 | C10: =C9*Assumptions!$B$4 -> 0 | D10: =D9*Assumptions!$B$4 -> -11430000
A11: After-tax proceeds — Heavy | B11: =B7-B10 -> 96012000 | C11: =C7-C10 -> 45720000 | D11: =D7-D10 -> 57150000
A12: Aux sold at book value (no tax) | B12: =Depreciation!D26 -> 38400000 | C12: =Depreciation!G26 -> 24000000 | D12: =Depreciation!L26 -> 0
A13: Causeway sold at book value (no tax) | B13: =Depreciation!D27 -> 41200000 | C13: =Depreciation!G27 -> 28000000 | D13: =Depreciation!L27 -> 12000000
A14: NWC recovery (end-year balance) | B14: ='Working Capital'!D9 -> 2.8116616e+08 | C14: ='Working Capital'!G9 -> 3.1212844e+08 | D14: ='Working Capital'!L9 -> 3.4591501e+08
A15: Total terminal cash flow | B15: =B11+B12+B13+B14 -> 4.5677816e+08 | C15: =C11+C12+C13+C14 -> 4.0984844e+08 | D15: =D11+D12+D13+D14 -> 4.1506501e+08
A17: NPV, IRR, PAYBACK
A18: WACC used | B18: =WACC!$B$26 -> 0.1106001 | C18: =WACC!$B$26 -> 0.1106001 | D18: =WACC!$B$26 -> 0.1106001
A19: NPV (₱ millions) | B19: =B26+NPV(WACC!$B$26,C26:D26) -> -59609070 | C19: =B27+NPV(WACC!$B$26,C27:G27) -> 1.9784316e+08 | D19: =B28+NPV(WACC!$B$26,C28:L28) -> 4.8432895e+08
A20: IRR | B20: =IRR(B26:D26) -> 0.051723841 | C20: =IRR(B27:G27) -> 0.19867798 | D20: =IRR(B28:L28) -> 0.23547073
A21: Payback period (yrs) | B21: =IF(MAX(B30:D30)<0,"No payback",COUNTIF(B30:D30,"<0")-1+ABS(INDEX(B30:D30,COUNTIF(B30:D30,"<0")))/INDEX(B26:D26,COUNTIF(B30:D30,"<0")+1)) -> 1.9033911 | C21: =IF(MAX(B31:G31)<0,"No payback",COUNTIF(B31:G31,"<0")-1+ABS(INDEX(B31:G31,COUNTIF(B31:G31,"<0")))/INDEX(B27:G27,COUNTIF(B31:G31,"<0")+1)) -> 4.0233835 | D21: =IF(MAX(B32:L32)<0,"No payback",COUNTIF(B32:L32,"<0")-1+ABS(INDEX(B32:L32,COUNTIF(B32:L32,"<0")))/INDEX(B28:L28,COUNTIF(B32:L32,"<0")+1)) -> 4.2746716
A22: Decision | B22: =IF(AND(B19>0,B20>WACC!$B$26,ISNUMBER(B21),B21<2),"ACCEPT",IF(AND(B19>0,B20>WACC!$B$26),"MEETS NPV/IRR (payback fails)","REJECT")) -> REJECT | C22: =IF(AND(C19>0,C20>WACC!$B$26,ISNUMBER(C21),C21<2),"ACCEPT",IF(AND(C19>0,C20>WACC!$B$26),"MEETS NPV/IRR (payback fails)","REJECT")) -> MEETS NPV/IRR (payback fails) | D22: =IF(AND(D19>0,D20>WACC!$B$26,ISNUMBER(D21),D21<2),"ACCEPT",IF(AND(D19>0,D20>WACC!$B$26),"MEETS NPV/IRR (payback fails)","REJECT")) -> MEETS NPV/IRR (payback fails)
A24: FCF Series (constructed for each scenario)
B25: Y0 | C25: Y1 | D25: Y2 | E25: Y3 | F25: Y4 | G25: Y5 | H25: Y6 | I25: Y7 | J25: Y8 | K25: Y9 | L25: Y10
A26: 2-Yr FCF | B26: ='P&L and FCF'!B42 -> -581500000 | C26: ='P&L and FCF'!C42 -> 8606704.8 | D26: ='P&L and FCF'!D42+B15 -> 6.3415867e+08 | E26: 0 | F26: 0 | G26: 0 | H26: 0 | I26: 0 | J26: 0 | K26: 0 | L26: 0
A27: 5-Yr FCF | B27: ='P&L and FCF'!B42 -> -581500000 | C27: ='P&L and FCF'!C42 -> 8606704.8 | D27: ='P&L and FCF'!D42 -> 1.7738051e+08 | E27: ='P&L and FCF'!E42 -> 1.860187e+08 | F27: ='P&L and FCF'!F42 -> 1.9512336e+08 | G27: ='P&L and FCF'!G42-'P&L and FCF'!G37+C15 -> 6.1456811e+08 | H27: 0 | I27: 0 | J27: 0 | K27: 0 | L27: 0
A28: 10-Yr FCF | B28: ='P&L and FCF'!B42 -> -581500000 | C28: ='P&L and FCF'!C42 -> 8606704.8 | D28: ='P&L and FCF'!D42 -> 1.7738051e+08 | E28: ='P&L and FCF'!E42 -> 1.860187e+08 | F28: ='P&L and FCF'!F42 -> 1.9512336e+08 | G28: ='P&L and FCF'!G42 -> 52319662 | H28: ='P&L and FCF'!H42 -> 2.0602508e+08 | I28: ='P&L and FCF'!I42 -> 2.1195773e+08 | ... K28: ='P&L and FCF'!K42 -> 2.2436232e+08 | L28: ='P&L and FCF'!L35+'P&L and FCF'!L36+'P&L and FCF'!L37+'P&L and FCF'!L38+D15 -> 6.4591009e+08
A30: 2-Yr cumulative FCF | B30: =B26 -> -581500000 | C30: =B30+C26 -> -5.728933e+08 | D30: =C30+D26 -> 61265374 | E30: =D30+E26 -> 61265374 | F30: =E30+F26 -> 61265374 | G30: =F30+G26 -> 61265374 | H30: =G30+H26 -> 61265374 | I30: =H30+I26 -> 61265374 | J30: =I30+J26 -> 61265374 | ... L30: =K30+L26 -> 61265374
A31: 5-Yr cumulative FCF | B31: =B27 -> -581500000 | C31: =B31+C27 -> -5.728933e+08 | D31: =C31+D27 -> -3.9551278e+08 | E31: =D31+E27 -> -2.0949408e+08 | F31: =E31+F27 -> -14370724 | G31: =F31+G27 -> 6.0019738e+08 | H31: =G31+H27 -> 6.0019738e+08 | I31: =H31+I27 -> 6.0019738e+08 | J31: =I31+J27 -> 6.0019738e+08 | ... L31: =K31+L27 -> 6.0019738e+08
A32: 10-Yr cumulative FCF | B32: =B28 -> -581500000 | C32: =B32+C28 -> -5.728933e+08 | D32: =C32+D28 -> -3.9551278e+08 | E32: =D32+E28 -> -2.0949408e+08 | F32: =E32+F28 -> -14370724 | G32: =F32+G28 -> 37948939 | H32: =G32+H28 -> 2.4397402e+08 | I32: =H32+I28 -> 4.5593175e+08 | J32: =I32+J28 -> 6.7400012e+08 | ... L32: =K32+L28 -> 1.5442725e+09
A35: Decision rules (per CFO Lascano):
A36: • Accept if NPV > 0 AND IRR > WACC → economic value created
A37: • Rodriguez also wants payback < 2 years → tighter recovery threshold
A40: SENSITIVITY ANALYSIS — 5-Year NPV (₱M) vs. Selling Price & WACC
A42: Selling price Y1 (₱/t) | B42: % vs. base | C42: Approx. ΔRevenue p.a. (₱M) | D42: Approx. ΔNPV (₱M)* | E42: 5-yr NPV (₱M)*
A43: 450 | B43: =A43/Assumptions!$B$10-1 -> -0.18181818 | C43: =(A43-Assumptions!$B$10)*Assumptions!$B$9/1000000 -> -300 | D43: =C43*0.705*((1-(1+WACC!$B$26)^-5)/WACC!$B$26) -> -780.50364 | E43: =Scenarios!$C$19/1000000+D43 -> -582.66048
A44: 500 | B44: =A44/Assumptions!$B$10-1 -> -0.090909091 | C44: =(A44-Assumptions!$B$10)*Assumptions!$B$9/1000000 -> -150 | D44: =C44*0.705*((1-(1+WACC!$B$26)^-5)/WACC!$B$26) -> -390.25182 | E44: =Scenarios!$C$19/1000000+D44 -> -192.40866
A45: 525 | B45: =A45/Assumptions!$B$10-1 -> -0.045454545 | C45: =(A45-Assumptions!$B$10)*Assumptions!$B$9/1000000 -> -75 | D45: =C45*0.705*((1-(1+WACC!$B$26)^-5)/WACC!$B$26) -> -195.12591 | E45: =Scenarios!$C$19/1000000+D45 -> 2.7172506
A46: 550 | B46: =A46/Assumptions!$B$10-1 -> 0 | C46: =(A46-Assumptions!$B$10)*Assumptions!$B$9/1000000 -> 0 | D46: =C46*0.705*((1-(1+WACC!$B$26)^-5)/WACC!$B$26) -> 0 | E46: =Scenarios!$C$19/1000000+D46 -> 197.84316
A47: 575 | B47: =A47/Assumptions!$B$10-1 -> 0.045454545 | C47: =(A47-Assumptions!$B$10)*Assumptions!$B$9/1000000 -> 75 | D47: =C47*0.705*((1-(1+WACC!$B$26)^-5)/WACC!$B$26) -> 195.12591 | E47: =Scenarios!$C$19/1000000+D47 -> 392.96907
A48: 600 | B48: =A48/Assumptions!$B$10-1 -> 0.090909091 | C48: =(A48-Assumptions!$B$10)*Assumptions!$B$9/1000000 -> 150 | D48: =C48*0.705*((1-(1+WACC!$B$26)^-5)/WACC!$B$26) -> 390.25182 | E48: =Scenarios!$C$19/1000000+D48 -> 588.09498
A49: 650 | B49: =A49/Assumptions!$B$10-1 -> 0.18181818 | C49: =(A49-Assumptions!$B$10)*Assumptions!$B$9/1000000 -> 300 | D49: =C49*0.705*((1-(1+WACC!$B$26)^-5)/WACC!$B$26) -> 780.50364 | E49: =Scenarios!$C$19/1000000+D49 -> 978.3468
A51: * Linear approximation around base case: ΔNPV ≈ ΔRevenue × (1 – tax – excise – local) × 5-yr annuity factor at WACC. Excludes the second-order effects of inflation, NWC re-sizing, and terminal value adjustments. For exact figures, edit Assumptions!B8 directly.

Sheet Sources & Notes
B1: SOURCES, NOTES & MODELING DECISIONS
B3: Section | C3: Notes
B4: CASE FACTS — All from Ivey W38382
B5: Rock armour selling price | C5: Page 5: ₱550/tonne Year 1 average (size grades range −9% to +5%)
B6: Production volume | C6: Page 5: "close to 3 million tonnes annually"
B7: Subcon hauling rate | C7: Exhibit 4: ₱250/t (drill+blast 100, bulldozing 35, road 35, drainage 10, stockpile 10, barge haul 60)
B8: Subcon loading rate | C8: Exhibit 4: ₱30/t for barge loading
B9: Fuel consumption | C9: Page 5: 641,842 litres/month at ₱55.70/litre Year 1
B10: Wages | C10: Page 5: 100 people, two 8-hour shifts, ₱2.5M/month total
B11: Other non-fuel monthly opex | C11: Page 5: ₱1.5M/month
B12: Heavy equipment maintenance | C12: Page 5: 5% of acquisition cost p.a., inflation-escalated
B13: Aux equipment maintenance | C13: Page 5: 2% of cost (excluding mess/office/accom which sum to ₱6M)
B14: Causeway maintenance | C14: Page 5: ½ of causeway depreciation
B15: Excise tax | C15: Page 3: 4% of revenue paid to national government (MPSA)
B16: Local government tax | C16: Page 3: 1% of revenue
... B25: Corporate tax | C25: Endnote 38: Philippine CIT = 25%
B27: MODELING DECISIONS
B28: Inflation rate | C28: Page 5 text says 5.40% (BSP forecast 2022). Exhibit 5 numerically uses 6.30% (Aug 2022 actual headline). Model uses 5.40% per text; Exhibit 5 numbers can be reproduced by setting Assumptions!B5 to 6.30%.
B29: Tax shield method | C29: WACC built on after-tax cost of debt. Tax applied to EBIT (no interest tax shield in unlevered FCF — captured in WACC).
B30: Risk-free rate tenor | C30: Selected 10-year BVAL to match industry-norm 10-year quarry life rather than 5-year contract horizon. This is the conservative choice; using 5-yr (5.57%) would lower WACC by ~50 bps and raise all NPVs.
B31: Year-5 rehab treatment | C31: Capitalized as new capex at end of Y5; depreciated over Y6–Y10 to a 12% Y10 salvage. For the 5-year scenario, we assume the project terminates at Y5 and rehab is NOT incurred (asset sold at heavy-equipment salvage instead).
B32: Terminal value tax | C32: Sale price minus book value gives gain/loss; gain taxed at 25%, loss creates a tax shield. Aux and causeway are sold at book in 2- and 5-yr scenarios (no gain/loss).
B33: Working capital recovery | C33: Full ending NWC balance (cash + inventory + AR – AP) is recovered as cash at the end of the project life in each scenario.
B34: NWC at Y0 | C34: Assumed equal to ₱102.5M (cash 100M + inventory 2.5M); funded by the bank loan. Working capital build for AR happens at Y1 onward as revenue starts.
B35: Discounting convention | C35: Discrete annual discounting; project cash flows treated as end-of-year. Year 0 capex undiscounted.
B36: IRR / payback | C36: IRR computed on the FCF series of each scenario. Payback uses cumulative undiscounted FCF, interpolated linearly across the year of recovery.
B38: LIMITATIONS
B39: No price/volume size mix | C39: The 3-grade size mix (300kg–1t / 1–3t / 3–6t) is collapsed into a single average price per Rodriguez's simplifying assumption.
B40: No FX hedging | C40: All cash flows in PHP. SMC contract is in PHP, so no direct FX exposure modeled.
B41: No counterparty risk modeling | C41: SMC is treated as a creditworthy counterparty. In reality, large infrastructure projects can experience payment delays.
B42: No tax loss carryforwards | C42: Loss-carryforward benefit on the Y1 EBIT (small) is ignored; tax floor of zero applied.
B43: No real options | C43: The option to extend beyond Y10 (under the 25-year MPSA) and the option to abandon mid-project are not valued.

Sheet Sources & Notes1
B1: SOURCES, NOTES & MODELING DECISIONS
B3: Section | C3: Notes
B4: CASE FACTS — All from Ivey W38382
B5: Rock armour selling price | C5: Page 5: ₱550/tonne Year 1 average (size grades range −9% to +5%)
B6: Production volume | C6: Page 5: "close to 3 million tonnes annually"
B7: Subcon hauling rate | C7: Exhibit 4: ₱250/t (drill+blast 100, bulldozing 35, road 35, drainage 10, stockpile 10, barge haul 60)
B8: Subcon loading rate | C8: Exhibit 4: ₱30/t for barge loading
B9: Fuel consumption | C9: Page 5: 641,842 litres/month at ₱55.70/litre Year 1
B10: Wages | C10: Page 5: 100 people, two 8-hour shifts, ₱2.5M/month total
B11: Other non-fuel monthly opex | C11: Page 5: ₱1.5M/month
B12: Heavy equipment maintenance | C12: Page 5: 5% of acquisition cost p.a., inflation-escalated
B13: Aux equipment maintenance | C13: Page 5: 2% of cost (excluding mess/office/accom which sum to ₱6M)
B14: Causeway maintenance | C14: Page 5: ½ of causeway depreciation
B15: Excise tax | C15: Page 3: 4% of revenue paid to national government (MPSA)
B16: Local government tax | C16: Page 3: 1% of revenue
... B25: Corporate tax | C25: Endnote 38: Philippine CIT = 25%
B27: MODELING DECISIONS
B28: Inflation rate | C28: Page 5 text says 5.40% (BSP forecast 2022). Exhibit 5 numerically uses 6.30% (Aug 2022 actual headline). Model uses 5.40% per text; Exhibit 5 numbers can be reproduced by setting Assumptions!B5 to 6.30%.
B29: Tax shield method | C29: WACC built on after-tax cost of debt. Tax applied to EBIT (no interest tax shield in unlevered FCF — captured in WACC).
B30: Risk-free rate tenor | C30: Selected 10-year BVAL to match industry-norm 10-year quarry life rather than 5-year contract horizon. This is the conservative choice; using 5-yr (5.57%) would lower WACC by ~50 bps and raise all NPVs.
B31: Year-5 rehab treatment | C31: Capitalized as new capex at end of Y5; depreciated over Y6–Y10 to a 12% Y10 salvage. For the 5-year scenario, we assume the project terminates at Y5 and rehab is NOT incurred (asset sold at heavy-equipment salvage instead).
B32: Terminal value tax | C32: Sale price minus book value gives gain/loss; gain taxed at 25%, loss creates a tax shield. Aux and causeway are sold at book in 2- and 5-yr scenarios (no gain/loss).
B33: Working capital recovery | C33: Full ending NWC balance (cash + inventory + AR – AP) is recovered as cash at the end of the project life in each scenario.
B34: NWC at Y0 | C34: Assumed equal to ₱102.5M (cash 100M + inventory 2.5M); funded by the bank loan. Working capital build for AR happens at Y1 onward as revenue starts.
B35: Discounting convention | C35: Discrete annual discounting; project cash flows treated as end-of-year. Year 0 capex undiscounted.
B36: IRR / payback | C36: IRR computed on the FCF series of each scenario. Payback uses cumulative undiscounted FCF, interpolated linearly across the year of recovery.
B38: LIMITATIONS
B39: No price/volume size mix | C39: The 3-grade size mix (300kg–1t / 1–3t / 3–6t) is collapsed into a single average price per Rodriguez's simplifying assumption.
B40: No FX hedging | C40: All cash flows in PHP. SMC contract is in PHP, so no direct FX exposure modeled.
B41: No counterparty risk modeling | C41: SMC is treated as a creditworthy counterparty. In reality, large infrastructure projects can experience payment delays.
B42: No tax loss carryforwards | C42: Loss-carryforward benefit on the Y1 EBIT (small) is ignored; tax floor of zero applied.
B43: No real options | C43: The option to extend beyond Y10 (under the 25-year MPSA) and the option to abandon mid-project are not valued.
